#include "stdafx.h"
#include "cut/common.h"
#include "cut/testing/unit-test-group.h"
#include "cut/testing/unit-test-manager.h"
#include "cut/testing/unit-test.h"
#include "cut/exceptions.h"
#include "cut/string-ref.h"
#include "cut/string-format.h"
#include "cut/logging/log-block.h"

cut::UnitTestGroup::UnitTestGroup(StringRef groupName, Lambda_t initialization, Lambda_t shutdown) :
	m_name(groupName),
	m_numFailedTests(0),
	m_initialization(initialization),
	m_shutdown(shutdown),
	m_unitTests()
{
	IUnitTestManager::instance().registerUnitTestGroup(this);
}

cut::UnitTestGroup::~UnitTestGroup()
{
}

void
cut::UnitTestGroup::registerUnitTest(IUnitTest* unitTest )
{
	m_unitTests.push_back(unitTest);
}

std::size_t
cut::UnitTestGroup::runAllTests()
{
	std::size_t failed = 0;
	if(m_initialization) { m_initialization(); }
	CUT_SCOPE_EXIT{ if(m_shutdown) { m_shutdown(); } };
	
	for (auto unitTest : m_unitTests)
	{
		auto unitTestName = unitTest->getName().cString();
		try
		{
			//logMessage(format("Running unit test \"%s\"...\n", unitTestName));
			LogBlock runSingleTest(format("Running test \"%s\"", unitTestName));
			unitTest->run();
			//logSuccess(format("Unit test \"%s\" succeeded!\n", unitTestName));
		}
		catch (exceptions::UnitTestFailure& failure)
		{
			++failed;

			if (failure.message().empty())
			{
				logFailure(format("Unit test \"%s\" failed in file %s at line %d.\n",
								  unitTestName,
								  failure.file(),
								  failure.line()));
			}
			else
			{
				logFailure(format("Unit test \"%s\" failed in file %s at line %d:\n  %s\n",
								  unitTestName,
								  failure.file(),
								  failure.line(),
								  failure.message().cString()));
			}
		}
		catch (exceptions::UnitTestSuccess& success)
		{
			if(success.message().empty())
			{
				logSuccess(format("Unit test \"%s\" succeeded prematurely in file %s at line %d.\n",
					unitTestName,
					success.file(),
					success.line()));
			}
			else
			{
				logSuccess(format("Unit test \"%s\" succeeded prematurely in file %s at line %d:\n  %s\n",
					unitTestName,
					success.file(),
					success.line(),
					success.message().cString()));
			}
		}
		catch (std::exception& ex)
		{
			++failed;
			logFailure(format("Unit test \"%s\" failed due to an unhandled std::exception: %s\n",
							  unitTestName,
							  ex.what()));
		}
		catch (...)
		{
			++failed;
			logFailure(format("Unit test \"%s\" failed due to an unknown exception.\n", unitTestName));
		}
	}
	return failed;
}

std::size_t
cut::UnitTestGroup::numberOfUnitTests()
{
	return m_unitTests.size();
}

cut::StringRef
cut::UnitTestGroup::getName() const
{
	return m_name;
}
